Workbook

Sheet Introduction
L1: YEAR | M1: 2024 | N1: 2025
A2: TVM | L2: Qtr | M2: 1q25 | N2: 2q25 | O2: 3q25 | P2: 4q25
L3: 1Q24 | M3: 2Q24
A4: Life is all about making choices so in finance we have choices | K4: Revenue | L4: 150 | M4: 200
A5: Eg | K5: Growth Rate | M5: =M4/L4-1 -> 0.33333333
A6: 1 | B6: If we want to buy a car -Buy in cash/loan | K6: Y/Y | L6: Q/Q
A7: 2 | B7: Redeem your investment to pay off your personal oan | K7: Revenue | L7: 150 | M7: =L7*(1+M8) -> 199.5 | N7: =L7*M8 -> 49.5 | O7: =L7+N7 -> 199.5
A8: 3 | B8: Create emergency with your savings or use line of credit during emergency | K8: Growth Rate | M8: 0.33
A9: It all depends on value of money today and what will be its value in future.
A10: This concept is called TVM | K10: Revenue | L10: 1000 | M10: Cost/Expenes | N10: 800
K11: Profit/loss | L11: =L10-N10 -> 200
A12: TVM is important concept which helps in making finance decision | K12: Margin | L12: =L11/L10 -> 0.2 | M12: % Revenue | N12: =N10/L10 -> 0.8
A13: so will dicuss
A15: 1 | B15: What is TVM
A16: 2 | B16: Two important concept of TVM
A17: 3 | B17: How to calculate.
A19: 1 | B19: What is TVM
A20: Ans - | B20: TVM means in passage of time the value of money changes
M21: PV | N21: 8000
A22: Eg | B22: Today Rs 100 in next 2 Years it will not remain Rs 100 & 2 years ago its value was more than todays Rs 100 | M22: FV | N22: 10000
M23: R | N23: 0.25
A24: 2 | B24: It is important to understand TVM because | M24: N | N24: 1
A25: Ans | B25: It helps in taking loan decesion | M25: FV | N25: PV | O25: R
B26: Why currency is depreciated | M26: =N26+O26 -> 10000 | N26: 8000 | O26: =8000*25% -> 2000
B27: Help in choosing the best asset class | M27: FV | N27: PV | O27: (1+R)
N28: PV*(1+R)^N
A30: Eg 1 | B30: Option A | D30: Option B
B31: Rs 5000 Today | D31: Rs 5000 - One year later
A32: Ans
K33: PV | N33: FV= PV*(1+R)^N | O33: FV | P33: MULITPLY
K34: No of years | L34: 1 | N34: PV = FV/(1+R)^N | P34: DIV
A35: Eg 2 | B35: Option A | D35: Option B | K35: FV
B36: Rs 5000 Today | D36: Rs 5500 - One year later | K36: Opprounity Rate | L36: 0.06 | N36: FV | O36: Compounding
B37: Presnt Value | C37: 5000 | F37: PV | G37: =G38/(1+L36)^L34 -> 5188.6792 | N37: PV | O37: Discounting
B38: FV | C38: =C37*(1+L36)^L34 -> 5300 | F38: future value | G38: 5500
A42: So to come to a decesion we need to understand 2 important concepts
A44: 1 | B44: Future Value | D44: FV | E44: Compounding | G44: Opporunity cost impact is added in FV
A45: 2 | B45: Present Value | D45: PV | E45: Discounting | G45: Opporunity cost impact is deducted in PV
A47: Eg 2 | B47: Option A | D47: Option B | F47: Assume Opportunity Cost | I47: 0.1
B48: Rs 5000 Today | D48: Rs 5500 - One year later
...

Sheet Sheet14

Sheet Sheet15

Sheet Sheet16

Sheet Sheet17

Sheet Sheet18

Sheet Sheet19

Sheet Sheet20

Sheet Sheet21

Sheet Question 
A1: Fund Selection Case Study
A3: Alister Cook is a mutual fund advisor in wealth advisors LLP, a large wealth management firm with 2000 Cr AUM and 100 wealthy clients. Alister cook has been given the task to analyse mutual fund returns of two very well know mutual fund schemes, Franklin tempelton Prima plus and SBI Gilt fund. The client Mr. Bhushan has been a client of wealth advisors for a decade, and is expecting an optimum allocation strategy between these two funds. He is willing to invest 15000 in total in these two schemes per month. You have been given the task to analyse the mutual fund scheme with historical returns given to you in the data sheet and present your results. Following are the assumptions given to you:
A6: Investment Per Month | C6: 15000
A7: Franklin Allocation | C7: 0.5
A8: SBI Allocation | C8: 0.5
A10: Tasks :
A11: 1. Using the database given of the NAV of two funds find out the return generated on 03-11-2016 on both funds seperately, as well as the return generated on the overall portfolio. Considering the redemption date as 14-10-2016
A12: 2. Create a data table with different allocations possible
A13: 3. Compare returns of FIPP against NIFTY 50 and conclude your results
A15: Points to remember
A16: 1. There is no right or wrong answer in this case, although task 1 will have a certain answer
A17: 2. Write any other concerns you might have while presenting your results
A18: 3. You are free to calculate any additional metrics you may find appropriate.
A22: Presentation
A23: · You will create a ppt presentation with your data calculated in the excel model
A24: · You will record a self presented audio video presentation and upload in in the learning portal
A25: · Trainer along with panelists will ask you questions in the assignment interview

Sheet MF Data
A1: 2013-2016- Franklin Tempelton Prima Plus | C1: 2013-16 SBI Debt | E1: SIP Dates
A2: Date | B2: NAV | C2: Date | D2: NAV | E2: FIPP | G2: SBI
A3: 41275 | B3: 253.6914 | C3: 41275 | D3: 23.1123 | E3: Date | G3: Date
A4: 41276 | B4: 254.5831 | C4: 41276 | D4: 23.1228 | E4: 41275 | F4: =B3 -> 253.6914 | G4: =C3 -> 41275
A5: 41277 | B5: 255.8842 | C5: 41277 | D5: 23.1967 | E5: 41305 | F5: =B25 -> 255.752 | G5: 41305
A6: 41278 | B6: 256.621 | C6: 41278 | D6: 23.2659 | E6: 41334 | G6: 41334
A7: 41281 | B7: 256.8791 | C7: 41281 | D7: 23.3557 | E7: 41365 | G7: 41366
A8: 41282 | B8: 256.8502 | C8: 41282 | D8: 23.3686 | E8: 41396 | G8: 41396
A9: 41283 | B9: 256.8864 | C9: 41283 | D9: 23.3917 | E9: 41425 | G9: 41425
A10: 41284 | B10: 256.9648 | C10: 41284 | D10: 23.4303 | E10: 41428 | G10: 41452
A11: 41285 | B11: 255.7857 | C11: 41285 | D11: 23.4693 | E11: 41485 | G11: 41485
A12: 41288 | B12: 258.2288 | C12: 41288 | D12: 23.6218 | E12: 41515 | G12: 41515
A13: 41289 | B13: 259.5659 | C13: 41289 | D13: 23.5646 | E13: 41547 | G13: 41547
A14: 41290 | B14: 257.3978 | C14: 41290 | D14: 23.4463 | E14: 41575 | G14: 41575
A15: 41291 | B15: 258.7803 | C15: 41291 | D15: 23.5172 | E15: 41605 | G15: 41605
A16: 41292 | B16: 258.1592 | C16: 41292 | D16: 23.5056 | E16: 41635 | G16: 41635
A17: 41295 | B17: 258.6886 | C17: 41295 | D17: 23.4957 | E17: 41666 | G17: 41666
... A50: 41340 | B50: 245.5322 | C50: 41344 | D50: 23.7307 | E50: 42656 | G50: 42657
A51: 41341 | B51: 247.6821 | C51: 41345 | D51: 23.7088 | E51: 42657 | G51: =G50 -> 42657
A52: 41344 | B52: 247.2433 | C52: 41346 | D52: 23.7084
A53: 41345 | B53: 246.2393 | C53: 41347 | D53: 23.7384
A54: 41346 | B54: 243.5775 | C54: 41348 | D54: 23.7483
A55: 41347 | B55: 245.0176 | C55: 41351 | D55: 23.7393
A56: 41348 | B56: 243.3638 | C56: 41352 | D56: 23.7257
A57: 41351 | B57: 241.7637 | C57: 41353 | D57: 23.7091
A58: 41352 | B58: 238.9957 | C58: 41354 | D58: 23.7043
A59: 41353 | B59: 236.4942 | C59: 41355 | D59: 23.694
A60: 41354 | B60: 236.3527 | C60: 41358 | D60: 23.7017
A61: 41355 | B61: 235.5823 | C61: 41359 | D61: 23.7188
A62: 41358 | B62: 234.9297 | C62: 41361 | D62: 23.7463
A63: 41359 | B63: 235.961 | C63: 41364 | D63: 23.7607
... A923: 42643 | B923: 485.8164 | C923: 42681 | D923: 35.239
A924: 42646 | B924: 492.2104
A925: 42647 | B925: 495.5407
A926: 42648 | B926: 496.0712
A927: 42649 | B927: 494.3399
A928: 42650 | B928: 493.8173
A929: 42653 | B929: 494.3557
A930: 42656 | B930: 488.3037
A931: 42657 | B931: 489.5995
...

Sheet Presentation
K1: Franklin | T1: SBI
F2: SIP | G2: 15000 | J2: =G6 -> 0.16645597 | K2: 0.5 | L2: 0.6 | M2: 0.7 | N2: 0.8 | O2: 0.9 | P2: 1 | S2: =G6 -> 0.16645597 | T2: 0.5 | U2: 0.6 | V2: 0.7 | W2: 0.8 | X2: 0.9 | Y2: 1
F3: SBI | G3: 0.5 | J3: 0.5 | K3: 0.16645597 | L3: 0.16830156 | M3: 0.16983585 | N3: 0.17113144 | O3: 0.17224005 | P3: 0.17319941 | S3: 0.5 | T3: 0.16645597 | U3: 0.16184213 | V3: 0.1579737 | W3: 0.15468348 | X3: 0.15185079 | Y3: 0.14938636
F4: Franklin | G4: 0.5 | J4: 0.4 | K4: 0.17205392 | L4: 0.17351143 | M4: 0.17470168 | N4: 0.17569202 | O4: 0.17652889 | P4: 0.17724542 | S4: 0.4 | T4: 0.16419358 | U4: 0.15932828 | V4: 0.15532203 | W4: 0.15196572 | X4: 0.14911297 | Y4: 0.14665834
F5: Total Portfolio | G5: =N60 -> 957903.06 | I5: SBI | J5: 0.3 | K5: 0.1789888 | L5: 0.17982671 | M5: 0.18049633 | N5: 0.18104371 | O5: 0.18149955 | P5: 0.18188501 | R5: Frank | S5: 0.3 | T5: 0.16135518 | U5: 0.15624337 | V5: 0.15212658 | W5: 0.14873998 | X5: 0.14590506 | Y5: 0.14349715
F6: Returns | G6: =N61 -> 0.16645597 | J6: 0.2 | K6: 0.18780537 | L6: 0.18764161 | M6: 0.18751422 | N6: 0.18741228 | O6: 0.18732888 | P6: 0.18725936 | S6: 0.2 | T6: 0.1576887 | U6: 0.15236781 | V6: 0.14820086 | W6: 0.14484909 | X6: 0.14209456 | Y6: 0.13979066
J7: 0.1 | K7: 0.19939151 | L7: 0.19756342 | M7: 0.19618924 | N7: 0.19511858 | O7: 0.19426088 | P7: 0.19355834 | S7: 0.1 | T7: 0.15276967 | U7: 0.14735282 | V7: 0.14326208 | W7: 0.14006352 | X7: 0.13749391 | Y7: 0.13538433
J8: 0 | K8: 0.21529984 | L8: 0.21057948 | M8: 0.20718852 | N8: 0.20463461 | O8: 0.20264186 | P8: 0.20104361 | S8: 0 | T8: 0.14582371 | U8: 0.14060892 | V8: 0.13685972 | W8: 0.13403432 | X8: 0.13182871 | Y8: 0.13005909
C10: Franklin | D10: Bhushan | E10: MF ACCOUNT | I10: SBI
A11: Date | B11: NAV | C11: Growth | D11: SIP | E11: Portfolio | G11: Date | H11: NAV | I11: Growth | J11: SIP | K11: Portfolio | M11: Date | N11: Total SIP | O11: Total Portfolio
A12: 41275 | B12: =VLOOKUP(A12,'MF Data'!A:B,2,0) -> 253.6914 | D12: =$G$2*$G$4*-1 -> -7500 | E12: 7500 | G12: 41275 | H12: =VLOOKUP(G12,'MF Data'!C:D,2,0) -> 23.1123 | J12: =$G$2*$G$3*-1 -> -7500 | K12: 7500 | M12: 41275 | N12: =D12+J12 -> -15000 | O12: =E12+K12 -> 15000
A13: 41305 | B13: =VLOOKUP(A13,'MF Data'!A:B,2,0) -> 255.752 | C13: =B13/B12-1 -> 0.0081224669 | D13: =$G$2*$G$4*-1 -> -7500 | E13: =E12*(1+C13)-D13 -> 15060.919 | G13: 41305 | H13: =VLOOKUP(G13,'MF Data'!C:D,2,0) -> 23.3886 | I13: =H13/H12-1 -> 0.011954673 | J13: =$G$2*$G$3*-1 -> -7500 | K13: =K12*(1+I13)-J13 -> 15089.66 | M13: 41305 | N13: =D13+J13 -> -15000 | O13: =E13+K13 -> 30150.579
A14: 41334 | B14: =VLOOKUP(A14,'MF Data'!A:B,2,0) -> 241.0424 | C14: =B14/B13-1 -> -0.057515093 | D14: =$G$2*$G$4*-1 -> -7500 | E14: =E13*(1+C14)-D14 -> 21694.688 | G14: 41334 | H14: =VLOOKUP(G14,'MF Data'!C:D,2,0) -> 23.627 | I14: =H14/H13-1 -> 0.010193 | J14: =$G$2*$G$3*-1 -> -7500 | K14: =K13*(1+I14)-J14 -> 22743.469 | M14: 41334 | N14: =D14+J14 -> -15000 | O14: =E14+K14 -> 44438.157
A15: 41365 | B15: =VLOOKUP(A15,'MF Data'!A:B,2,0) -> 239.0403 | C15: =B15/B14-1 -> -0.0083060076 | D15: =$G$2*$G$4*-1 -> -7500 | E15: =E14*(1+C15)-D15 -> 29014.492 | G15: 41366 | H15: =VLOOKUP(G15,'MF Data'!C:D,2,0) -> 23.745 | I15: =H15/H14-1 -> 0.0049942862 | J15: =$G$2*$G$3*-1 -> -7500 | K15: =K14*(1+I15)-J15 -> 30357.056 | M15: 41365 | N15: =D15+J15 -> -15000 | O15: =E15+K15 -> 59371.548
A16: 41396 | B16: =VLOOKUP(A16,'MF Data'!A:B,2,0) -> 244.8839 | C16: =B16/B15-1 -> 0.024446087 | D16: =$G$2*$G$4*-1 -> -7500 | E16: =E15*(1+C16)-D16 -> 37223.783 | G16: 41396 | H16: =VLOOKUP(G16,'MF Data'!C:D,2,0) -> 24.2897 | I16: =H16/H15-1 -> 0.022939566 | J16: =$G$2*$G$3*-1 -> -7500 | K16: =K15*(1+I16)-J16 -> 38553.434 | M16: 41396 | N16: =D16+J16 -> -15000 | O16: =E16+K16 -> 75777.217
A17: 41425 | B17: =VLOOKUP(A17,'MF Data'!A:B,2,0) -> 246.4601 | C17: =B17/B16-1 -> 0.0064365195 | D17: =$G$2*$G$4*-1 -> -7500 | E17: =E16*(1+C17)-D17 -> 44963.375 | G17: 41425 | H17: =VLOOKUP(G17,'MF Data'!C:D,2,0) -> 25.2493 | I17: =H17/H16-1 -> 0.039506457 | J17: =$G$2*$G$3*-1 -> -7500 | K17: =K16*(1+I17)-J17 -> 47576.544 | M17: 41425 | N17: =D17+J17 -> -15000 | O17: =E17+K17 -> 92539.918
A18: 41428 | B18: =VLOOKUP(A18,'MF Data'!A:B,2,0) -> 247.6493 | C18: =B18/B17-1 -> 0.0048251218 | D18: =$G$2*$G$4*-1 -> -7500 | E18: =E17*(1+C18)-D18 -> 52680.328 | G18: 41452 | H18: =VLOOKUP(G18,'MF Data'!C:D,2,0) -> 24.9902 | I18: =H18/H17-1 -> -0.010261671 | J18: =$G$2*$G$3*-1 -> -7500 | K18: =K17*(1+I18)-J18 -> 54588.329 | M18: 41428 | N18: =D18+J18 -> -15000 | O18: =E18+K18 -> 107268.66
A19: 41485 | B19: =VLOOKUP(A19,'MF Data'!A:B,2,0) -> 233.9652 | C19: =B19/B18-1 -> -0.055255961 | D19: =$G$2*$G$4*-1 -> -7500 | E19: =E18*(1+C19)-D19 -> 57269.426 | G19: 41485 | H19: =VLOOKUP(G19,'MF Data'!C:D,2,0) -> 24.3595 | I19: =H19/H18-1 -> -0.025237893 | J19: =$G$2*$G$3*-1 -> -7500 | K19: =K18*(1+I19)-J19 -> 60710.634 | M19: 41485 | N19: =D19+J19 -> -15000 | O19: =E19+K19 -> 117980.06
A20: 41515 | B20: =VLOOKUP(A20,'MF Data'!A:B,2,0) -> 222.2782 | C20: =B20/B19-1 -> -0.049951873 | D20: =$G$2*$G$4*-1 -> -7500 | E20: =E19*(1+C20)-D20 -> 61908.711 | G20: 41515 | H20: =VLOOKUP(G20,'MF Data'!C:D,2,0) -> 23.7871 | I20: =H20/H19-1 -> -0.023498019 | J20: =$G$2*$G$3*-1 -> -7500 | K20: =K19*(1+I20)-J20 -> 66784.055 | M20: 41515 | N20: =D20+J20 -> -15000 | O20: =E20+K20 -> 128692.77
A21: 41547 | B21: =VLOOKUP(A21,'MF Data'!A:B,2,0) -> 236.0835 | C21: =B21/B20-1 -> 0.062108205 | D21: =$G$2*$G$4*-1 -> -7500 | E21: =E20*(1+C21)-D21 -> 73253.75 | G21: 41547 | H21: =VLOOKUP(G21,'MF Data'!C:D,2,0) -> 24.0315 | I21: =H21/H20-1 -> 0.010274477 | J21: =$G$2*$G$3*-1 -> -7500 | K21: =K20*(1+I21)-J21 -> 74970.226 | M21: 41547 | N21: =D21+J21 -> -15000 | O21: =E21+K21 -> 148223.98
A22: 41575 | B22: =VLOOKUP(A22,'MF Data'!A:B,2,0) -> 249.2703 | C22: =B22/B21-1 -> 0.055856508 | D22: =$G$2*$G$4*-1 -> -7500 | E22: =E21*(1+C22)-D22 -> 84845.449 | G22: 41575 | H22: =VLOOKUP(G22,'MF Data'!C:D,2,0) -> 24.4984 | I22: =H22/H21-1 -> 0.019428667 | J22: =$G$2*$G$3*-1 -> -7500 | K22: =K21*(1+I22)-J22 -> 83926.797 | M22: 41575 | N22: =D22+J22 -> -15000 | O22: =E22+K22 -> 168772.25
A23: 41605 | B23: =VLOOKUP(A23,'MF Data'!A:B,2,0) -> 252.8934 | C23: =B23/B22-1 -> 0.014534824 | D23: =$G$2*$G$4*-1 -> -7500 | E23: =E22*(1+C23)-D23 -> 93578.662 | G23: 41605 | H23: =VLOOKUP(G23,'MF Data'!C:D,2,0) -> 24.3774 | I23: =H23/H22-1 -> -0.0049390981 | J23: =$G$2*$G$3*-1 -> -7500 | K23: =K22*(1+I23)-J23 -> 91012.275 | M23: 41605 | N23: =D23+J23 -> -15000 | O23: =E23+K23 -> 184590.94
A24: 41635 | B24: =VLOOKUP(A24,'MF Data'!A:B,2,0) -> 266.6727 | C24: =B24/B23-1 -> 0.054486594 | D24: =$G$2*$G$4*-1 -> -7500 | E24: =E23*(1+C24)-D24 -> 106177.44 | G24: 41635 | H24: =VLOOKUP(G24,'MF Data'!C:D,2,0) -> 24.2633 | I24: =H24/H23-1 -> -0.0046805648 | J24: =$G$2*$G$3*-1 -> -7500 | K24: =K23*(1+I24)-J24 -> 98086.286 | M24: 41635 | N24: =D24+J24 -> -15000 | O24: =E24+K24 -> 204263.73
... A58: 42656 | B58: =VLOOKUP(A58,'MF Data'!A:B,2,0) -> 488.3037 | C58: =B58/B57-1 -> 0.0017834195 | D58: =$G$2*$G$4*-1 -> -7500 | E58: =E57*(1+C58)-D58 -> 509489.11 | G58: 42656 | H58: =VLOOKUP(G58,'MF Data'!C:D,2,0) -> 35.3276 | I58: =H58/H57-1 -> 0.020781082 | J58: =$G$2*$G$3*-1 -> -7500 | K58: =K57*(1+I58)-J58 -> 447769.18 | M58: 42656 | N58: =D58+J58 -> -15000 | O58: =E58+K58 -> 957258.29
A59: 42657 | B59: =VLOOKUP(A59,'MF Data'!A:B,2,0) -> 489.5995 | C59: =B59/B58-1 -> 0.0026536764 | E59: =E58*(1+C59)-D59 -> 510841.13 | G59: 42657 | H59: =VLOOKUP(G59,'MF Data'!C:D,2,0) -> 35.2718 | I59: =H59/H58-1 -> -0.0015795016 | K59: =K58*(1+I59)-J59 -> 447061.93 | M59: 42657 | N59: =D59+J59 -> 0 | O59: =E59+K59 -> 957903.06
A60: =A59 -> 42657 | D60: =E59 -> 510841.13 | G60: =G59 -> 42657 | J60: =K59 -> 447061.93 | M60: 42657 | N60: =D60+J60 -> 957903.06 | O60: =E60+K60 -> 0
B61: XIRR | C61: =XIRR(D12:D60,A12:A60) -> 0.20272415 | D61: =XIRR(D12:D60,A12:A60) -> 0.20272415 | H61: XIRR | I61: =XIRR(J12:J60,G12:G60) -> 0.12831427 | M61: XIRR | N61: =XIRR(N12:N60,M12:M60) -> 0.16645597
B62: XIRR | C62: =XIRR(D12:D60,A12:A60) -> 0.20272415
D63: =XIRR(D12:D60,A12:A60) -> 0.20272415
